I'm sorry, but an uncaught exception occurred.

While running game code:
  File "game/chapter_2.rpy", line 1457, in script call
    menu:
  File "game/after_load.rpy", line 2, in script
    $ inventory.drop(dildo)
  File "game/after_load.rpy", line 2, in <module>
    $ inventory.drop(dildo)
  File "game/sandbox_elements/money_system.rpy", line 41, in drop
    self.items.remove(item)
ValueError: list.remove(x): x not in list

-- Full Traceback ------------------------------------------------------------

Full traceback:
  File "game/chapter_2.rpy", line 1457, in script call
    menu:
  File "game/after_load.rpy", line 2, in script
    $ inventory.drop(dildo)
  File "D:\Renpy projects\New Beginings In Japan\dialog data\renpy-8.0.3-sdk\renpy\ast.py", line 1131, in execute
    renpy.python.py_exec_bytecode(self.code.bytecode, self.hide, store=self.store)
  File "D:\Renpy projects\New Beginings In Japan\dialog data\renpy-8.0.3-sdk\renpy\python.py", line 1061, in py_exec_bytecode
    exec(bytecode, globals, locals)
  File "game/after_load.rpy", line 2, in <module>
    $ inventory.drop(dildo)
  File "game/sandbox_elements/money_system.rpy", line 41, in drop
    self.items.remove(item)
  File "D:\Renpy projects\New Beginings In Japan\dialog data\renpy-8.0.3-sdk\renpy\revertable.py", line 97, in do_mutation
    return method(self, *args, **kwargs)
ValueError: list.remove(x): x not in list

Windows-10-10.0.19045 AMD64
Ren'Py 8.0.3.22090809
 0.3
Tue May 30 23:03:27 2023
